Traceback (most recent call last):
  File "main.py", line 2, in <module>
    import mlflow
  File "/home/sca63/.local/lib/python3.8/site-packages/mlflow/__init__.py", line 52, in <module>
    import mlflow.fastai as fastai  # noqa: E402
  File "/home/sca63/.local/lib/python3.8/site-packages/mlflow/fastai.py", line 19, in <module>
    import pandas as pd
  File "/share/apps/anaconda3/2021.05/lib/python3.8/site-packages/pandas/__init__.py", line 29, in <module>
    from pandas._libs import hashtable as _hashtable, lib as _lib, tslib as _tslib
  File "/share/apps/anaconda3/2021.05/lib/python3.8/site-packages/pandas/_libs/__init__.py", line 13, in <module>
    from pandas._libs.interval import Interval
  File "pandas/_libs/interval.pyx", line 1, in init pandas._libs.interval
ValueError: numpy.ndarray size changed, may indicate binary incompatibility. Expected 88 from C header, got 80 from PyObject
